Workbook

Sheet קבלת חומרי גלם
A1: שם הספק | B1: תאריך קבלה | C1: סוג | D1: סוג חומר הגלם | E1: משקל/כמות [ק"ג] | F1: תוקף חומר הגלם | G1: עבר מעשר | H1: בעל תקן משרד הבריאות | I1: בעל תעודת כשל"פ
A2: תמרתושקה | C2: תבלינים | D2: זרעי כוסברה | E2: 1 | F2: 45983 | K2: סוג | M2: תבלינים | O2: תויות | Q2: אריזות | S2: סוג מוצר
A3: ניחוחות ארגמן | C3: תבלינים | D3: ליקריץ | E3: 0.86 | F3: 45921 | K3: תויות | M3: כוכב אניס | O3: תויות ערק צוואר | Q3: בקבוק אובלו (ברנדי) | S3: EDV
A4: תמרתושקה | C4: תבלינים | D4: קינמון | E4: 0.32 | F4: 45912 | K4: אריזות | M4: זרעי אניס | O4: תויות ערק | Q4: בקבוק דמוס (ג'ין, EDV) | S4: ערק
A5: תמרתושקה | C5: תבלינים | D5: הל | E5: 0.63 | F5: 45910 | K5: תבלינים | M5: ליקריץ | O5: תויות ליקריץ' צוואר | Q5: בקבוק לוב (ארק ליקריץ') | S5: ג'ין
A6: תמרתושקה | C6: תבלינים | D6: קמומיל | E6: 0.88 | F6: 45903 | M6: ערער | O6: תויות ליקריץ' | Q6: פקק - דמוס | S6: ליקריץ
A7: ניחוחות ארגמן | C7: תבלינים | D7: כוכב אניס | E7: 0.81 | F7: 45920 | M7: הל | O7: תויות ג'ין צוואר | Q7: פקק - אובלו, לוב | S7: ברנדי VS
A8: תמרתושקה | C8: תבלינים | D8: זרעי אניס | E8: 0.44 | F8: 45940 | M8: קינמון | O8: תויות ג'ין | Q8: קרטון 6 - אובלו (ברנדי) | S8: ברנדי VSOP
A9: תמרתושקה | C9: תבלינים | D9: פירות הדר לימון | E9: 0.24 | F9: 45931 | M9: קמומיל | O9: תויות EDV צוואר | Q9: קרטון 6 - דמוס (ג'ין, EDV) | S9: ברנדי חורש ים תיכוני
A10: תמרתושקה | C10: תבלינים | D10: פירות הדר תפוז | E10: 1.32 | F10: 45931 | M10: זרעי כוסברה | O10: תויות EDV | Q10: קרטון 6 - לוב (ארק ליקריץ')
A11: ליקוט עצמי | C11: תבלינים | D11: שיזף | E11: 3.69 | F11: 45931 | M11: פירות הדר תפוז | O11: תויות ברנדי VS צוואר | Q11: קרטון בקבוק יחד
A12: ליקוט עצמי | C12: תבלינים | D12: חרובים | E12: 0.33 | F12: 45931 | M12: פירות הדר לימון | O12: תויות ברנדי VS | Q12: קרטון 12 אובלו
A13: I-HERB | C13: תבלינים | D13: זרעי כוסברה | E13: 0.2 | F13: 46578 | M13: פרעושית | O13: תויות ברנדי VSOP צוואר | Q13: קרטון 12 דמוס
A14: I-HERB | C14: תבלינים | D14: ערער | E14: 0.93 | F14: 46487 | M14: כוכב ריחני | O14: תויות ברנדי VSOP | Q14: קרטון 12 לוב
A15: ש.ל.ר | B15: התחלה | C15: תויות | D15: תויות ברנדי VSOP | E15: 1000 | M15: שיזף | O15: תוית פקק נחושת | Q15: חביות
A16: ש.ל.ר | B16: התחלה | C16: תויות | D16: תויות ברנדי VS | E16: 997 | M16: חרובים | O16: תוית פקק זהב
A17: ש.ל.ר | B17: התחלה | C17: תויות | D17: תויות ג'ין | E17: 676 | M17: קטלב
A18: ש.ל.ר | B18: התחלה | C18: תויות | D18: תויות EDV | E18: 700 | M18: אשחר
A19: ש.ל.ר | B19: התחלה | C19: תויות | D19: תויות ליקריץ' | E19: 900 | M19: אלה
A20: ש.ל.ר | B20: התחלה | C20: תויות | D20: תויות ערק | E20: 400
A21: ש.ל.ר | B21: התחלה | C21: תויות | D21: תוית פקק נחושת | E21: 3530
A22: ש.ל.ר | B22: התחלה | C22: תויות | D22: תוית פקק זהב | E22: 1710
A23: ש.ל.ר | B23: התחלה | C23: תויות | D23: תויות ליקריץ' צוואר | E23: 800
A24: ש.ל.ר | B24: התחלה | C24: תויות | D24: תויות ערק צוואר | E24: 400
A25: ש.ל.ר | B25: התחלה | C25: תויות | D25: תויות ברנדי VS צוואר | E25: 997
A26: ש.ל.ר | B26: התחלה | C26: תויות | D26: תויות ברנדי VSOP צוואר | E26: 1000
A27: ש.ל.ר | B27: התחלה | C27: תויות | D27: תויות EDV צוואר | E27: 700
A28: ש.ל.ר | B28: התחלה | C28: תויות | D28: תויות ג'ין צוואר | E28: 650
A29: יקב האלה | B29: התחלה | C29: אריזות | D29: חביות | E29: 4
A30: PCSI | B30: התחלה | C30: אריזות | D30: פקק - אובלו, לוב | E30: 1745
A31: PCSI | B31: התחלה | C31: אריזות | D31: פקק - דמוס | E31: 950
... A34: PCSI | B34: התחלה | C34: אריזות | D34: בקבוק לוב (ארק ליקריץ') | E34: 1200
A35: קטיף עצמי | B35: 45657 | C35: תבלינים | D35: קטלב | E35: 1.36 | F35: 46022 | G35: לא | H35: לא
A36: הכנה ליקריץ | B36: 45657 | C36: תבלינים | D36: ליקריץ | E36: -0.26 | F36: \ | G36: כן | H36: כן
A37: ניחוחות ארגמן | B37: 45694 | C37: תבלינים | D37: ליקריץ | E37: 400 | G37: כן | H37: כן

Sheet קבלת תמרים
A1: שם הספק | B1: תאריך קבלה | C1: משקל [ק"ג] | D1: מעשר - בוצע/לא בוצע | E1: תוקף חומר הגלם | F1: כמות בתוקף | G1: הערות
A2: התחלה - גמלאיל | B2: 45655 | C2: 3600 | D2: כן | E2: שנה | F2: =IF(B2<EDATE(TODAY(),-12), 0, קבלת_תמרים[[#This Row],[משקל '[ק"ג']]]) -> 0 | H2: =SUM(קבלת_תמרים[[#All],[כמות בתוקף]]) -> 14175
A3: התחלה - ארגזים כתומים | B3: 45655 | C3: 8200 | D3: כן | E3: שנה | F3: =IF(B3<EDATE(TODAY(),-12), 0, קבלת_תמרים[[#This Row],[משקל '[ק"ג']]]) -> 0
A4: גמליאל | B4: 45662 | C4: 400 | D4: כן | E4: שנה | F4: =IF(B4<EDATE(TODAY(),-12), 0, קבלת_תמרים[[#This Row],[משקל '[ק"ג']]]) -> 0
A5: גמליאל | B5: 45676 | C5: 400 | D5: כן | E5: שנה | F5: =IF(B5<EDATE(TODAY(),-12), 0, קבלת_תמרים[[#This Row],[משקל '[ק"ג']]]) -> 0
A6: גמליאל | B6: 45686 | C6: 400 | D6: כן | E6: שנה | F6: =IF(B6<EDATE(TODAY(),-12), 0, קבלת_תמרים[[#This Row],[משקל '[ק"ג']]]) -> 0
A7: לארה | B7: 45686 | C7: 1000 | D7: כן | E7: שנה | F7: =IF(B7<EDATE(TODAY(),-12), 0, קבלת_תמרים[[#This Row],[משקל '[ק"ג']]]) -> 0
A8: לארה | B8: 45753 | C8: 400 | D8: כן | E8: שנה | F8: =IF(B8<EDATE(TODAY(),-12), 0, קבלת_תמרים[[#This Row],[משקל '[ק"ג']]]) -> 400
A9: גמליאל | B9: ספטמבר-אוקטובר | C9: 12550 | D9: כן | E9: שנה | F9: =IF(B9<EDATE(TODAY(),-12), 0, קבלת_תמרים[[#This Row],[משקל '[ק"ג']]]) -> 12550 | G9: 05.11.2025 - 502 ארגזים כתומים
A10: גמליאל | B10: 45974 | C10: 1225 | D10: כן | E10: שנה | F10: =IF(B10<EDATE(TODAY(),-12), 0, קבלת_תמרים[[#This Row],[משקל '[ק"ג']]]) -> 1225 | G10: 49 ארגזים כתומים
F11: =IF(B11<EDATE(TODAY(),-12), 0, קבלת_תמרים[[#This Row],[משקל '[ק"ג']]]) -> 0
F12: =IF(B12<EDATE(TODAY(),-12), 0, קבלת_תמרים[[#This Row],[משקל '[ק"ג']]]) -> 0
F13: =IF(B13<EDATE(TODAY(),-12), 0, קבלת_תמרים[[#This Row],[משקל '[ק"ג']]]) -> 0
F14: =IF(B14<EDATE(TODAY(),-12), 0, קבלת_תמרים[[#This Row],[משקל '[ק"ג']]]) -> 0
F15: =IF(B15<EDATE(TODAY(),-12), 0, קבלת_תמרים[[#This Row],[משקל '[ק"ג']]]) -> 0
F16: =IF(B16<EDATE(TODAY(),-12), 0, קבלת_תמרים[[#This Row],[משקל '[ק"ג']]]) -> 0
F17: =IF(B17<EDATE(TODAY(),-12), 0, קבלת_תמרים[[#This Row],[משקל '[ק"ג']]]) -> 0
F18: =IF(B18<EDATE(TODAY(),-12), 0, קבלת_תמרים[[#This Row],[משקל '[ק"ג']]]) -> 0
F19: =IF(B19<EDATE(TODAY(),-12), 0, קבלת_תמרים[[#This Row],[משקל '[ק"ג']]]) -> 0
F20: =IF(B20<EDATE(TODAY(),-12), 0, קבלת_תמרים[[#This Row],[משקל '[ק"ג']]]) -> 0
F21: =IF(B21<EDATE(TODAY(),-12), 0, קבלת_תמרים[[#This Row],[משקל '[ק"ג']]]) -> 0
F22: =IF(B22<EDATE(TODAY(),-12), 0, קבלת_תמרים[[#This Row],[משקל '[ק"ג']]]) -> 0
... F97: =IF(B97<EDATE(TODAY(),-12), 0, קבלת_תמרים[[#This Row],[משקל '[ק"ג']]]) -> 0
F98: =SUM(קבלת_תמרים[כמות בתוקף]) -> 14175

Sheet תסיסה
A1: תאריך | B1: גודל מיכל | C1: תמרים [ק"ג] | D1: כמות (ליטר) | E1: טמפרטורה (°C) | F1: כמות סוכרים | G1: pH | H1: יצא לזיקוק | I1: הערות
A2: 45617 | B2: 1000 | C2: =280/1000*תסיסה[[#This Row],[גודל מיכל]] -> 280 | D2: 0 | K2: =SUM(תסיסה[תמרים '[ק"ג']]) -> 12824 | L2: כמות תמרים במהלך תסיסה
A3: 45623 | B3: 1000 | C3: =280/1000*תסיסה[[#This Row],[גודל מיכל]] -> 280 | D3: 0
A4: 45629 | B4: 500 | C4: =280/1000*תסיסה[[#This Row],[גודל מיכל]] -> 140 | D4: =תסיסה[[#This Row],[גודל מיכל]] - SUMIFS(זיקוק_1[כמות זיקוק מהתססה], זיקוק_1[תאריך תסיסה], ">="&תסיסה[[#This Row],[תאריך]], זיקוק_1[תאריך תסיסה], "<="&תסיסה[[#This Row],[תאריך]]) -> 0 | K4: =4*1000+2*500+2*200 -> 5400 | L4: סה"כ מיכלים פעילים בל'
A5: 45631 | B5: 500 | C5: =280/1000*תסיסה[[#This Row],[גודל מיכל]] -> 140 | D5: =תסיסה[[#This Row],[גודל מיכל]] - SUMIFS(זיקוק_1[כמות זיקוק מהתססה], זיקוק_1[תאריך תסיסה], ">="&תסיסה[[#This Row],[תאריך]], זיקוק_1[תאריך תסיסה], "<="&תסיסה[[#This Row],[תאריך]]) -> 0
A6: 45636 | B6: 1000 | C6: =280/1000*תסיסה[[#This Row],[גודל מיכל]] -> 280 | D6: =תסיסה[[#This Row],[גודל מיכל]] - SUMIFS(זיקוק_1[כמות זיקוק מהתססה], זיקוק_1[תאריך תסיסה], ">="&תסיסה[[#This Row],[תאריך]], זיקוק_1[תאריך תסיסה], "<="&תסיסה[[#This Row],[תאריך]]) -> 0
A7: 45642 | B7: 1000 | C7: =280/1000*תסיסה[[#This Row],[גודל מיכל]] -> 280 | D7: =תסיסה[[#This Row],[גודל מיכל]] - SUMIFS(זיקוק_1[כמות זיקוק מהתססה], זיקוק_1[תאריך תסיסה], ">="&תסיסה[[#This Row],[תאריך]], זיקוק_1[תאריך תסיסה], "<="&תסיסה[[#This Row],[תאריך]]) -> 0
A8: 45646 | B8: 900 | C8: =280/1000*תסיסה[[#This Row],[גודל מיכל]] -> 252 | D8: =תסיסה[[#This Row],[גודל מיכל]] - SUMIFS(זיקוק_1[כמות זיקוק מהתססה], זיקוק_1[תאריך תסיסה], ">="&תסיסה[[#This Row],[תאריך]], זיקוק_1[תאריך תסיסה], "<="&תסיסה[[#This Row],[תאריך]]) -> 0
A9: 45651 | B9: 400 | C9: =280/1000*תסיסה[[#This Row],[גודל מיכל]] -> 112 | D9: =תסיסה[[#This Row],[גודל מיכל]] - SUMIFS(זיקוק_1[כמות זיקוק מהתססה], זיקוק_1[תאריך תסיסה], ">="&תסיסה[[#This Row],[תאריך]], זיקוק_1[תאריך תסיסה], "<="&תסיסה[[#This Row],[תאריך]]) -> 0
A10: 45657 | B10: 1000 | C10: =280/1000*תסיסה[[#This Row],[גודל מיכל]] -> 280 | D10: =תסיסה[[#This Row],[גודל מיכל]] - SUMIFS(זיקוק_1[כמות זיקוק מהתססה], זיקוק_1[תאריך תסיסה], ">="&תסיסה[[#This Row],[תאריך]], זיקוק_1[תאריך תסיסה], "<="&תסיסה[[#This Row],[תאריך]]) -> 0
A11: 45662 | B11: 500 | C11: =280/1000*תסיסה[[#This Row],[גודל מיכל]] -> 140 | D11: =תסיסה[[#This Row],[גודל מיכל]] - SUMIFS(זיקוק_1[כמות זיקוק מהתססה], זיקוק_1[תאריך תסיסה], ">="&תסיסה[[#This Row],[תאריך]], זיקוק_1[תאריך תסיסה], "<="&תסיסה[[#This Row],[תאריך]]) -> 0
A12: 45669 | B12: 1000 | C12: =280/1000*תסיסה[[#This Row],[גודל מיכל]] -> 280 | D12: =תסיסה[[#This Row],[גודל מיכל]] - SUMIFS(זיקוק_1[כמות זיקוק מהתססה], זיקוק_1[תאריך תסיסה], ">="&תסיסה[[#This Row],[תאריך]], זיקוק_1[תאריך תסיסה], "<="&תסיסה[[#This Row],[תאריך]]) -> 0
A13: 45676 | B13: 1000 | C13: =280/1000*תסיסה[[#This Row],[גודל מיכל]] -> 280 | D13: =תסיסה[[#This Row],[גודל מיכל]] - SUMIFS(זיקוק_1[כמות זיקוק מהתססה], זיקוק_1[תאריך תסיסה], ">="&תסיסה[[#This Row],[תאריך]], זיקוק_1[תאריך תסיסה], "<="&תסיסה[[#This Row],[תאריך]]) -> 100
A14: 45684 | B14: 1000 | C14: =280/1000*תסיסה[[#This Row],[גודל מיכל]] -> 280 | D14: =תסיסה[[#This Row],[גודל מיכל]] - SUMIFS(זיקוק_1[כמות זיקוק מהתססה], זיקוק_1[תאריך תסיסה], ">="&תסיסה[[#This Row],[תאריך]], זיקוק_1[תאריך תסיסה], "<="&תסיסה[[#This Row],[תאריך]]) -> 0
A15: 45692 | B15: 1000 | C15: =280/1000*תסיסה[[#This Row],[גודל מיכל]] -> 280 | D15: =תסיסה[[#This Row],[גודל מיכל]] - SUMIFS(זיקוק_1[כמות זיקוק מהתססה], זיקוק_1[תאריך תסיסה], ">="&תסיסה[[#This Row],[תאריך]], זיקוק_1[תאריך תסיסה], "<="&תסיסה[[#This Row],[תאריך]]) -> 100
A16: 45695 | B16: 1000 | C16: =280/1000*תסיסה[[#This Row],[גודל מיכל]] -> 280 | D16: =תסיסה[[#This Row],[גודל מיכל]] - SUMIFS(זיקוק_1[כמות זיקוק מהתססה], זיקוק_1[תאריך תסיסה], ">="&תסיסה[[#This Row],[תאריך]], זיקוק_1[תאריך תסיסה], "<="&תסיסה[[#This Row],[תאריך]]) -> 100
... A36: 45834 | B36: 1000 | C36: =280/1000*תסיסה[[#This Row],[גודל מיכל]] -> 280 | D36: =תסיסה[[#This Row],[גודל מיכל]] - SUMIFS(זיקוק_1[כמות זיקוק מהתססה], זיקוק_1[תאריך תסיסה], ">="&תסיסה[[#This Row],[תאריך]], זיקוק_1[תאריך תסיסה], "<="&תסיסה[[#This Row],[תאריך]]) -> 50
A37: 26/06/2025-2 | B37: 1000 | C37: =280/1000*תסיסה[[#This Row],[גודל מיכל]] -> 280 | D37: =תסיסה[[#This Row],[גודל מיכל]] - SUMIFS(זיקוק_1[כמות זיקוק מהתססה], זיקוק_1[תאריך תסיסה], ">="&תסיסה[[#This Row],[תאריך]], זיקוק_1[תאריך תסיסה], "<="&תסיסה[[#This Row],[תאריך]]) -> 100
A38: 45840 | B38: 1000 | C38: =280/1000*תסיסה[[#This Row],[גודל מיכל]] -> 280 | D38: =תסיסה[[#This Row],[גודל מיכל]] - SUMIFS(זיקוק_1[כמות זיקוק מהתססה], זיקוק_1[תאריך תסיסה], ">="&תסיסה[[#This Row],[תאריך]], זיקוק_1[תאריך תסיסה], "<="&תסיסה[[#This Row],[תאריך]]) -> -80
A39: 45844 | B39: 1000 | C39: =280/1000*תסיסה[[#This Row],[גודל מיכל]] -> 280 | D39: =תסיסה[[#This Row],[גודל מיכל]] - SUMIFS(זיקוק_1[כמות זיקוק מהתססה], זיקוק_1[תאריך תסיסה], ">="&תסיסה[[#This Row],[תאריך]], זיקוק_1[תאריך תסיסה], "<="&תסיסה[[#This Row],[תאריך]]) -> 100
A40: 45863 | B40: 1000 | C40: =280/1000*תסיסה[[#This Row],[גודל מיכל]] -> 280 | D40: =תסיסה[[#This Row],[גודל מיכל]] - SUMIFS(זיקוק_1[כמות זיקוק מהתססה], זיקוק_1[תאריך תסיסה], ">="&תסיסה[[#This Row],[תאריך]], זיקוק_1[תאריך תסיסה], "<="&תסיסה[[#This Row],[תאריך]]) -> 100
A41: 45868 | B41: 1000 | C41: =280/1000*תסיסה[[#This Row],[גודל מיכל]] -> 280 | D41: =תסיסה[[#This Row],[גודל מיכל]] - SUMIFS(זיקוק_1[כמות זיקוק מהתססה], זיקוק_1[תאריך תסיסה], ">="&תסיסה[[#This Row],[תאריך]], זיקוק_1[תאריך תסיסה], "<="&תסיסה[[#This Row],[תאריך]]) -> 100
A42: 45872 | B42: 1000 | C42: =280/1000*תסיסה[[#This Row],[גודל מיכל]] -> 280 | D42: =תסיסה[[#This Row],[גודל מיכל]] - SUMIFS(זיקוק_1[כמות זיקוק מהתססה], זיקוק_1[תאריך תסיסה], ">="&תסיסה[[#This Row],[תאריך]], זיקוק_1[תאריך תסיסה], "<="&תסיסה[[#This Row],[תאריך]]) -> -50
A43: 45883 | B43: 1000 | C43: =280/1000*תסיסה[[#This Row],[גודל מיכל]] -> 280 | D43: =תסיסה[[#This Row],[גודל מיכל]] - SUMIFS(זיקוק_1[כמות זיקוק מהתססה], זיקוק_1[תאריך תסיסה], ">="&תסיסה[[#This Row],[תאריך]], זיקוק_1[תאריך תסיסה], "<="&תסיסה[[#This Row],[תאריך]]) -> 100
A44: 45884 | B44: 500 | C44: =280/1000*תסיסה[[#This Row],[גודל מיכל]] -> 140 | D44: =תסיסה[[#This Row],[גודל מיכל]] - SUMIFS(זיקוק_1[כמות זיקוק מהתססה], זיקוק_1[תאריך תסיסה], ">="&תסיסה[[#This Row],[תאריך]], זיקוק_1[תאריך תסיסה], "<="&תסיסה[[#This Row],[תאריך]]) -> 50
A45: 45887 | B45: 1000 | C45: =280/1000*תסיסה[[#This Row],[גודל מיכל]] -> 280 | D45: =תסיסה[[#This Row],[גודל מיכל]] - SUMIFS(זיקוק_1[כמות זיקוק מהתססה], זיקוק_1[תאריך תסיסה], ">="&תסיסה[[#This Row],[תאריך]], זיקוק_1[תאריך תסיסה], "<="&תסיסה[[#This Row],[תאריך]]) -> 100
A46: 45919 | B46: 500 | C46: =280/1000*תסיסה[[#This Row],[גודל מיכל]] -> 140 | D46: =תסיסה[[#This Row],[גודל מיכל]] - SUMIFS(זיקוק_1[כמות זיקוק מהתססה], זיקוק_1[תאריך תסיסה], ">="&תסיסה[[#This Row],[תאריך]], זיקוק_1[תאריך תסיסה], "<="&תסיסה[[#This Row],[תאריך]]) -> 50
A47: 45896 | B47: 1000 | C47: =280/1000*תסיסה[[#This Row],[גודל מיכל]] -> 280 | D47: =תסיסה[[#This Row],[גודל מיכל]] - SUMIFS(זיקוק_1[כמות זיקוק מהתססה], זיקוק_1[תאריך תסיסה], ">="&תסיסה[[#This Row],[תאריך]], זיקוק_1[תאריך תסיסה], "<="&תסיסה[[#This Row],[תאריך]]) -> -350
A48: 45900 | B48: 1000 | C48: =280/1000*תסיסה[[#This Row],[גודל מיכל]] -> 280 | D48: =תסיסה[[#This Row],[גודל מיכל]] - SUMIFS(זיקוק_1[כמות זיקוק מהתססה], זיקוק_1[תאריך תסיסה], ">="&תסיסה[[#This Row],[תאריך]], זיקוק_1[תאריך תסיסה], "<="&תסיסה[[#This Row],[תאריך]]) -> 0
A49: 45910 | B49: 1000 | C49: =280/1000*תסיסה[[#This Row],[גודל מיכל]] -> 280 | D49: =תסיסה[[#This Row],[גודל מיכל]] - SUMIFS(זיקוק_1[כמות זיקוק מהתססה], זיקוק_1[תאריך תסיסה], ">="&תסיסה[[#This Row],[תאריך]], זיקוק_1[תאריך תסיסה], "<="&תסיסה[[#This Row],[תאריך]]) -> 650
C50: =280/1000*תסיסה[[#This Row],[גודל מיכל]] -> 0 | D50: =תסיסה[[#This Row],[גודל מיכל]] - SUMIFS(זיקוק_1[כמות זיקוק מהתססה], זיקוק_1[תאריך תסיסה], ">="&תסיסה[[#This Row],[תאריך]], זיקוק_1[תאריך תסיסה], "<="&תסיסה[[#This Row],[תאריך]]) -> 0
C51: =280/1000*תסיסה[[#This Row],[גודל מיכל]] -> 0 | D51: =תסיסה[[#This Row],[גודל מיכל]] - SUMIFS(זיקוק_1[כמות זיקוק מהתססה], זיקוק_1[תאריך תסיסה], ">="&תסיסה[[#This Row],[תאריך]], זיקוק_1[תאריך תסיסה], "<="&תסיסה[[#This Row],[תאריך]]) -> 0
C52: =280/1000*תסיסה[[#This Row],[גודל מיכל]] -> 0 | D52: =תסיסה[[#This Row],[גודל מיכל]] - SUMIFS(זיקוק_1[כמות זיקוק מהתססה], זיקוק_1[תאריך תסיסה], ">="&תסיסה[[#This Row],[תאריך]], זיקוק_1[תאריך תסיסה], "<="&תסיסה[[#This Row],[תאריך]]) -> 0
A53: 45958 | B53: 1000 | C53: =280/1000*תסיסה[[#This Row],[גודל מיכל]] -> 280 | D53: =תסיסה[[#This Row],[גודל מיכל]] - SUMIFS(זיקוק_1[כמות זיקוק מהתססה], זיקוק_1[תאריך תסיסה], ">="&תסיסה[[#This Row],[תאריך]], זיקוק_1[תאריך תסיסה], "<="&תסיסה[[#This Row],[תאריך]]) -> 1000 | I53: נכנסו 15 ארזי תמרים במקום 18 כמו שטנפון שם עד כה

Sheet זיקוק 1
A1: תאריך | B1: סוג | C1: שם המזקקה | D1: תאריך תסיסה | E1: כמות זיקוק מהתססה | F1: ריכוז אלכוהול התחלתי (%) | G1: טמפרטורה (°C) ושעה - ריכוז התחלתי | H1: סיום זיקוק ריכוז אלכוהול בסוף (%) | I1: טמפרטורה (°C) | J1: זמן (דקות) | K1: כמות מזוקקת [ליטר] | L1: הערות
A2: 22.12.2024 | B2: זנבות ערק | C2: אמיתי | D2: 45638 | E2: 0 | F2: 0.55 | H2: 0.2 | I2: 99.9 | J2: 16:30-18:15 | K2: 10 | N2: =SUM(זיקוק_1[כמות זיקוק מהתססה]) -> 40400
A3: 45649 | B3: זנבות ג'ין | C3: אמיתי | D3: \ | E3: 0 | F3: 0.55 | H3: 20 | I3: 99.9 | J3: 14:00-15:14 | K3: 10
A4: 45650 | B4: זיקוק 1 | C4: אמיתי | D4: \ | E4: 130 | F4: \ | H4: 20 | I4: 99.9 | J4: \ | K4: 16
A5: 45650 | B5: זיקוק 1 | C5: אמיתי | D5: \ | E5: 130 | F5: \ | H5: 20 | I5: 99.9 | J5: \ | K5: 16
A6: 45651 | B6: זיקוק 1 | C6: אמיתי | D6: \ | E6: 130 | F6: \ | H6: 20 | I6: 99.9 | J6: 07:00-13:00 | K6: 16
A7: 45652 | B7: זיקוק 1 | C7: אמיתי | D7: 45623 | E7: 130 | F7: 60 | H7: 20 | I7: 99.9 | J7: 07:00-13:30 | K7: 16
A8: 45653 | B8: זיקוק 1 | C8: אמיתי | D8: 45623 | E8: 130 | F8: 60 | H8: 20 | I8: 99.9 | J8: 07:00-13:00
A9: 45655 | B9: זיקוק 1 | C9: אמיתי | D9: 45623 | E9: 130 | F9: 60 | H9: 20 | I9: 99.9 | J9: 09:00-15:30
A10: 45656 | B10: זיקוק 1 | C10: אמיתי | D10: 45623 | E10: 130 | F10: 60 | H10: 18 | I10: 99.9 | J10: 07:00-13:30
A11: 45656 | B11: זיקוק 1 | C11: אמיתי | D11: 45623 | E11: 130 | F11: 60 | H11: 20 | I11: 99.9 | J11: 13:00-19:00
A12: 45657 | B12: זיקוק 1 | C12: אמיתי | D12: 45623 | E12: 130 | F12: 69 | H12: 18 | I12: 99.9 | J12: 07:20-13:25 | K12: 20
A13: 45627 | B13: זיקוק 1 | C13: אמיתי | D13: 45629 | E13: 130 | F13: 70 | H13: 25 | I13: 99.9 | J13: 08:30-14:30 | K13: 20
A14: 45293 | B14: זיקוק 1 | C14: אמיתי | D14: 45629 | E14: 130 | F14: 65 | H14: 23 | I14: 99.9 | J14: 09:30-16:00 | K14: 22
A15: 45294 | B15: זיקוק 1 | C15: אמיתי | D15: 45629 | E15: 130 | F15: 70 | H15: 20 | I15: 99.9 | J15: 07:00-12:00 | K15: 23
A16: 45662 | B16: זיקוק 1 | C16: אמיתי | D16: 45629 | E16: 110 | F16: 59 | H16: 18 | I16: 99.9 | J16: 06:45-13:00 | K16: 20
A17: 45663 | B17: זנבות EDV | C17: אמיתי | D17: \ | E17: \ | F17: 0.55 | I17: 99.9 | J17: 14:00-15:40 | K17: 15
A18: 45664 | B18: זנבות EDV | C18: אמיתי | D18: \ | E18: \ | F18: 0.55 | I18: 99.9 | K18: 15
A19: 45665 | B19: זיקוק 1 | C19: אמיתי | D19: 45631 | E19: 130 | F19: 60 | H19: 25 | I19: 99.9 | J19: 06:45-12:30 | K19: 26
A20: 45666 | B20: זיקוק 1 | C20: אמיתי | D20: 45631 | E20: 130 | F20: 62 | H20: 22 | I20: 99.9 | J20: 06:30-12:00 | K20: 20
A21: 45667 | B21: זיקוק 1 | C21: אמיתי | D21: 45631 | E21: 130 | F21: \ | H21: \ | I21: 99.9 | J21: 06:30-13:00 | K21: 20 | L21: נשבר מד אכוהול לכן אין מדידות עד שיהיה חדש
A22: 45669 | B22: זיקוק 1 | C22: אמיתי | D22: 45631 | E22: 110 | F22: \ | H22: \ | I22: 99.9 | J22: 07:00-13:30 | K22: 15 | L22: זוקק רק פעם 1 היום מ2 מיכלי תסיסה שונים
A23: 45669 | B23: זיקוק 1 | C23: אמיתי | D23: 45636 | E23: 110 | F23: \ | H23: \ | I23: 99.9 | J23: 07:00-13:30 | K23: 5 | L23: זוקק רק פעם 1 היום מ2 מיכלי תסיסה שונים
A24: 45670 | B24: זיקוק 1 | C24: אמיתי | D24: 45636 | E24: 140 | F24: \ | H24: \ | I24: 99.9 | J24: 06:30-13:00 | K24: 20 | L24: נשבר מד אכוהול לכן אין מדידות עד שיהיה חדש
A25: 45671 | B25: זיקוק 1 | C25: אמיתי | D25: 45636 | E25: 140 | F25: \ | H25: \ | I25: 99.9 | J25: 06:30-13:00 | K25: 22
A26: 45672 | B26: זיקוק 1 | C26: אמיתי | D26: 45636 | E26: 140 | F26: \ | H26: \ | I26: 99.9 | J26: 06:30-13:00 | K26: 20
A27: 45673 | B27: זיקוק 1 | C27: אמיתי | D27: 45636 | E27: 140 | F27: \ | H27: \ | I27: 99.9 | J27: 06:40-13:00 | K27: 20
A28: 45674 | B28: זיקוק 1 | C28: אמיתי | D28: 45636 | E28: 140 | F28: 45 | H28: 23 | I28: 99.9 | J28: 06:35-11:29 | K28: 15
A29: 45676 | B29: זיקוק 1 | C29: אמיתי | D29: 45636 | E29: 140 | F29: 52 | H29: 20 | I29: 99.9 | J29: 06:40-11:45 | K29: 19
A30: 45677 | B30: זיקוק 1 | C30: אמיתי | D30: 45636 | E30: 50 | F30: 55 | H30: 20 | I30: 99.9 | J30: 06:40-14:00 | K30: 22
A31: 45677 | B31: זיקוק 1 | C31: אמיתי | D31: 45642 | E31: 100 | F31: \ | H31: \ | I31: 99.9 | J31: \ | K31: \ | L31: אותו זיקוק כמו שורה מעל
A32: 45679 | B32: זיקוק 1 | C32: אמיתי | D32: 45642 | E32: 150 | F32: 55 | H32: 20 | I32: 99.9 | J32: 06:35-14:25 | K32: 15
A33: 45680 | B33: זיקוק 1 | C33: אמיתי | D33: 45642 | E33: 150 | F33: 67 | H33: 25 | I33: 99.9 | J33: 06:30-16:30 | K33: 25
A34: 45681 | B34: זיקוק 1 | C34: אמיתי | D34: 45642 | E34: 150 | F34: 65 | H34: 25 | I34: 99.9 | J34: 06:30-12:50 | K34: 17
A35: 45683 | B35: זיקוק 1 | C35: אמיתי | D35: 45642 | E35: 150 | F35: 64 | H35: 24 | I35: 99.9 | J35: 06:40-13:15 | K35: 18
A36: 45683 | B36: זיקוק 1 | C36: אמיתי | D36: 45642 | E36: 150 | F36: 64 | H36: 25 | I36: 99.9 | J36: 14:45-20:17 | K36: 18
A37: 45684 | B37: זיקוק 1 | C37: אמיתי | D37: 45642 | E37: 150 | F37: 57 | H37: 22 | I37: 99.9 | J37: 07:20-13:30 | K37: 17
A38: 45685 | B38: זנבות EDV | C38: אמיתי | D38: \ | E38: \ | F38: 55 | H38: 20 | I38: 99.9 | J38: 15:30-17:14 | K38: 12
A39: 45686 | B39: זנבות EDV | C39: אמיתי | D39: \ | E39: \ | F39: 55 | I39: 99.9 | J39: 0.63194444
A40: 45687 | B40: זנבות ערק | C40: אמיתי | D40: \ | E40: \ | F40: 55 | H40: 20 | I40: 99.9 | J40: 16:00-18:00 | K40: 12
...

Sheet זיקוק 2
A1: תאריך | B1: סוג | C1: תאריכי זיקוק 1 | D1: מספר אצווה (Batch) | E1: ריכוז אלכוהול התחלתי (%) | F1: הפרדת ראש 5 ל | G1: הפרדת זנבות ריכוז אלכוהול בסוף (%) | H1: טמפרטורה (°C) | I1: זמן (עד 55%) | J1: כמות (ליטר) | K1: הערות
B2: EDV | D2: E50
A3: 22.12.2024 | B3: ערק | D3: A101 | E3: 80 | F3: כן | G3: 0.55 | H3: 99.9 | I3: 08:00-18:15 | J3: 68
A4: 23.12.2024 | B4: ג'ין | D4: G6 | E4: 80 | F4: כן | G4: 0.55 | H4: 99.9 | I4: 07:00-15:15 | J4: 62
A5: 06.01.2025 | B5: EDV | C5: 1.1.25/2.1.25/5.1.25 | D5: E51 | E5: 80 | F5: כן | G5: 0.55 | H5: 99.9 | I5: 07:00-14:00 | J5: 64
A6: 07.01.2025 | B6: EDV | C6: 24.12 / 25.12 / מיכלי פלסטיק | D6: E52 | E6: 75 | F6: כן | G6: 0.55 | H6: 99.9 | I6: 06:45-14:10 | J6: 56.5
A7: 28.01.2025 | B7: EDV | C7: 7.1 - 8.1 - 10.1 - 13.1 - 22.1 | D7: E53 | E7: 80 | F7: כן | G7: 0.55 | H7: 99.9 | I7: 07:00-15:30 | J7: 56.6
A8: 29.01.2025 | B8: EDV | C8: 14.1 - 15.1 - 16.1 - 19.1 - | D8: E54 | E8: 77 | F8: כן | G8: 0.55 | H8: 99.9 | I8: 0.29166667 | J8: 56
A9: 30.01.2025 | B9: ערק | C9: 23.1 - 24.1 - 26.1 - 27.1 - 28.1 | D9: A102 | E9: 80 | F9: כן | G9: 0.55 | H9: 99.9 | I9: 07:00-16:00 | J9: 57 | K9: 290
A10: 12.02.2025 | B10: ג'ין | C10: 2.2 - 3.2 - 7.2 - 10.1 | D10: G7 | E10: 81 | F10: כן | G10: 0.55 | H10: 99.9 | I10: 07:20-15:30 | J10: 51
A11: 13.02.2025 | B11: EDV | C11: 30.1 - 4.2 - 6.2 - 12.2 - 2.2 | D11: E55 | E11: 81 | F11: כן | G11: 0.55 | H11: 99.9 | I11: 07:30-15:20 | J11: 51
A12: 20.02.2025 | B12: EDV | C12: 16.2 - 13.2 - 17.2 - | D12: E56 | E12: 82 | F12: כן | G12: 0.55 | H12: 99.9 | I12: 07:00-15:20 | J12: 56.6 | K12: 159
A13: 01.03.2025 | B13: ערק | C13: 25.2 - 27.2 - 20.2 - 26.2 - 10.2 | D13: A103 | E13: 80 | F13: כן | G13: 0.55 | H13: 99.9 | I13: 07:30-15:15 | J13: 50
A14: 13.03.2025 | B14: EDV | C14: 5.2 - 2.2 - 12.2 - 25.2 - 11.2 - 10.2 | D14: E57 | E14: 80 | F14: כן | G14: 0.55 | H14: 99.9 | I14: 07:20-15:30 | J14: 64
A15: 27.03.2025 | B15: ערק | D15: A104 | E15: 80 | F15: כן | G15: 0.55 | H15: 99.9 | I15: 07:00-15:20 | J15: 56
A16: 31.03.2025 | B16: ג'ין | D16: G8 | E16: 80 | F16: כן | G16: 0.55 | H16: 99.9 | I16: 07:00-15:15 | J16: 51
A17: 07.03.2025 | B17: ערק | C17: 14.3 - 18.3 - 20.3 - 31.3 | D17: A105 | E17: 82 | F17: כן | G17: 0.55 | H17: 99.9 | I17: 07:20-16:00 | J17: 60
A18: 09.03.2025 | B18: EDV | C18: 6.4 - 27.3 - 28.3 | D18: E58 | E18: 81 | F18: כן | G18: 0.55 | H18: 99.9 | I18: 07:25-15:45 | J18: 52 | K18: 333
A19: 20.04.2025 | B19: EDV | C19: 7.4 - 10.4 - 11.4 - 18.4 | D19: E59 | E19: 82 | F19: כן | G19: 0.55 | H19: 99.9 | I19: 07:00-14:45 | J19: 53
A20: 21.04.2025 | B20: ג'ין | C20: 2.4 - 3.4 - 4.4 - 25.3 | D20: G9 | E20: 81 | F20: כן | G20: 0.55 | H20: 99.9 | I20: 07:00-14:40 | J20: 55 | K20: 108
A21: 01.05.2025 | B21: ערק | C21: 15.4 | D21: A106 | E21: 80 | F21: כן | G21: 0.54 | H21: 99.9 | I21: 0.30243056 | J21: 60
A22: 18.05.2025 | B22: ג'ין | C22: 30.4 | D22: G10 | E22: 83 | F22: כן | G22: 0.56 | H22: 99.9 | I22: 06:45-14:30 | J22: 51
A23: 19.05.2025 | B23: EDV | C23: 11.4 - 13.4 - 4.4 - 6.4 | D23: E60 | E23: 80 | F23: כן | G23: 0.56 | H23: 99.9 | I23: 07:00 - 15:00 | J23: 51
A24: 20.05.2025 | B24: ערק | C24: 30.4 - 1-6/5 | D24: A107 | E24: 81 | F24: כן | G24: 0.56 | H24: 99.9 | I24: 07:00 - 14:35 | J24: 49 | K24: 211
A25: 11.06.2025 | B25: ערק | C25: 22.5 - 23.5 - 25.5 - 4.6 | D25: A108 | E25: 82 | F25: כן | G25: 0.55 | H25: 99.9 | I25: 06:40-14:50 | J25: 49
A26: 12.06.2025 | B26: ג'ין | C26: 30.5 - 6.6 - 8.6 | D26: G11 | E26: 85 | F26: כן | G26: 0.56 | H26: 99.9 | I26: 07:00-14:50 | J26: 55
A27: 15.06.2025 | B27: EDV | C27: 25.5 - 11.6 - 10.6 - 9.6 | D27: E61 | E27: 81 | F27: כן | G27: 0.53 | H27: 99.9 | I27: 07:00-14:45 | J27: 45
A28: 30.06.2025 | B28: EDV | C28: 17.6-19.6-24.6-14.6 | D28: E62 | E28: 81 | F28: כן | G28: 0.55 | H28: 99.9 | I28: 07:15-16:00 | J28: 51 | K28: 200
A29: 01.07.2025 | B29: EDV | C29: 26.6-22.6-25.6 | D29: E63 | E29: 80 | F29: כן | G29: 0.55 | H29: 99.9 | I29: 06:50-14:25 | J29: 54
A30: 10.07.2025 | B30: EDV | C30: 6.7-3.7-9.7 | D30: E64 | E30: 83 | F30: כן | G30: 0.55 | H30: 99.9 | I30: 06:50-14:25 | J30: 54
A31: 13.07.2025 | B31: ערק | D31: A109 | E31: 80 | F31: כן | G31: 0.55 | H31: 99.9 | I31: 07:10-14:20 | J31: 56 | K31: 164
A32: 13.08.2025 | B32: EDV | D32: E65 | E32: 85 | F32: כן | G32: 0.55 | H32: 99.9 | I32: 07:00-15:00 | J32: 53
A33: 20.08.2025 | B33: ג'ין | C33: 29.7 - 31.7 - 18.8 | D33: G12 | E33: 82 | F33: כן | G33: 0.55 | H33: 99.9 | I33: 07:40-14:30 | J33: 50
A34: 21.08.2025 | B34: ערק | C34: 13.8 - 25.7 - 30.7 - 17.8 | D34: A110 | E34: 78 | F34: כן | G34: 0.55 | H34: 99.9 | I34: 07:15-15:00 | J34: 56
A35: 24.08.2025 | B35: EDV | C35: 3.8 - 4.8 - 5.8 - 14.8 | D35: E66 | E35: 80 | F35: כן | G35: 0.55 | H35: 99.9 | I35: 07:00-14:00 | J35: 50
A36: 25.08.2025 | B36: EDV | C36: 18.8 - 20.8 - 29.8 - 23.8 | D36: E67 | E36: 83 | F36: כן | G36: 0.55 | H36: 99.9 | I36: 06:50-15:00 | J36: 50
A37: 14.09.2025 | B37: ערק | C37: 11.9 - 9.9 - 31.9 - 7.9 | D37: A111 | E37: 85 | F37: כן | G37: 0.55 | H37: 99.9 | I37: 07:30-15:50 | J37: 33* | K37: חסר נתונים
A38: 15.09.2025 | B38: ג'ין | C38: 9.9 - 7.9 - 25.8 - 26.8 - 27.8 | D38: G13 | E38: 83 | F38: כן | G38: 0.55 | H38: 99.9 | I38: 07:20-15:50 | J38: 66
A39: 25.09.2025 | B39: ערק | C39: 17.9 - 19.9 - 21.9 - 22.9 | D39: A112 | E39: 81 | F39: כן | G39: 0.55 | H39: 99.9 | I39: 07:00-16:30 | J39: 70
A40: 12.10.2025 | B40: EDV | C40: 9.9 - 18.9 - 31.9 - 8.9 - 29.9 | D40: E68 | E40: 87 | F40: כן | G40: 0.55 | H40: 99.9 | I40: 06:50-15:20 | J40: 56
...

Sheet ביקבוק
A1: סוג משקה | B1: תאריך בקבוק | C1: מספר אצווה (Batch) | D1: מספר חבית | E1: תאריך זיקוק 2 | F1: ריכוז אלכוהול (%) | G1: עבר סינון | H1: צבע | I1: טעם וריח | J1: היעדר מזהמים | K1: כמות בקבוקים | L1: החלטה | M1: חתימת אחראי איכות | N1: הערות
G2: כן / לא | H2: תקין / לא | I2: תקין / לא | J2: כן / לא | L2: מאושר / לא מאושר
A3: ערק | B3: התחלה | C3: A101 | F3: 0.37 | G3: כן | H3: תקין | I3: תקין | J3: כן | K3: 135 | L3: מאושר | M3: יון!
A4: ערק | B4: 26.12.2024 | C4: A101 | E4: 22.12.2024 | F4: 0.37 | G4: כן | H4: תקין | I4: תקין | J4: כן | K4: 60 | L4: מאושר | M4: יון!
A5: ערק | B5: 27.12.2024 | C5: A101 | E5: 22.12.2024 | F5: 0.37 | G5: כן | H5: תקין | I5: תקין | J5: כן | K5: 119 | L5: מאושר | M5: יון!
A6: ערק | B6: 29.12.2024 | C6: A101 | E6: 22.12.2024 | F6: 0.37 | G6: כן | H6: תקין | I6: תקין | J6: כן | K6: 58 | L6: מאושר | M6: יון!
A7: ג'ין | B7: התחלה | C7: G5 | F7: 0.37 | G7: כן | H7: תקין | I7: תקין | J7: כן | K7: 166 | L7: מאושר | M7: יון!
A8: EDV | B8: התחלה | C8: E50 | F8: 0.37 | G8: כן | H8: תקין | I8: תקין | J8: כן | K8: 95 | L8: מאושר | M8: יון!
A9: ליקריץ | B9: התחלה | C9: E50 | F9: 0.37 | G9: כן | H9: תקין | I9: תקין | J9: כן | K9: 0 | L9: מאושר | M9: יון!
A10: ברנדי VS | D10: B1 | F10: 0.46 | K10: 7 | L10: חבית (220ל')
A11: ברנדי VSOP | C11: 0 | K11: 0
A12: ליקריץ | B12: 45655 | C12: E51 | E12: התחלה | F12: 0.37 | G12: כן | H12: תקין | I12: תקין | J12: כן | K12: 150 | L12: מאושר | M12: יון!
A13: ליקריץ | C13: E51
A14: ברנדי VS | B14: 45664 | C14: E50+E51 | D14: B2 | E14: 21.01.2024 | F14: 0.55 | G14: כן | H14: תקין | I14: תקין | J14: כן | K14: חבית (220ל')
A15: ג'ין | B15: 45674 | C15: G6 | E15: 23.12.2025 | F15: 0.37 | G15: כן | H15: תקין | I15: תקין | J15: כן | K15: 138 | L15: מאושר | M15: יון!
A16: EDV | B16: 45683 | C16: E51+E52 | E16: 6-7.1.2025 | F16: 0.37 | G16: כן | H16: תקין | I16: תקין | J16: כן | K16: 105 | L16: מאושר | M16: יון!
A17: ליקריץ | B17: 45707 | C17: E52+E53 | E17: 7.1.2025 + 28.1.2025 | F17: 0.37 | G17: כן | H17: תקין | I17: תקין | J17: כן | K17: 143 | L17: מאושר | M17: יון!
A18: ברנדי VS | B18: 45708 | D18: B1 | F18: 0.46 | G18: כן | H18: תקין | I18: תקין | J18: כן | K18: 108 | L18: מאושר | M18: יון!
A19: ערק | B19: 45714 | C19: A102 | E19: 30.1.2025 | F19: 0.37 | G19: כן | H19: תקין | I19: תקין | J19: כן | K19: 173 | L19: מאושר | M19: יון!
A20: ליקריץ | B20: 45715 | C20: E52+E53 | E20: 7.1.2025 + 28.1.2025 | F20: 0.37 | G20: כן | H20: תקין | I20: תקין | J20: כן | K20: 42 | L20: מאושר | M20: יון!
A21: ג'ין | B21: 45728 | C21: G7 | E21: 12.02.2025 | F21: 0.37 | G21: כן | H21: תקין | I21: תקין | J21: כן | K21: 186 | L21: מאושר | M21: יון!
A22: ערק | B22: 45729 | C22: A103 | E22: 01.03.2025 | F22: 0.37 | G22: כן | H22: תקין | I22: תקין | J22: כן | K22: 203 | L22: מאושר | M22: יון!
A23: ברנדי VS | B23: 45732 | D23: B1 | F23: 0.46 | G23: כן | H23: תקין | I23: תקין | J23: כן | K23: 130 | L23: מאושר | M23: יון!
A24: ברנדי VS | B24: 45736 | D24: B3 | E24: 17.03.2025 | F24: 0.55 | G24: כן | H24: תקין | I24: תקין | J24: כן | K24: חבית (220ל') | L24: מאושר | M24: יון!
A25: ליקריץ | B25: 45750 | C25: E55 | E25: 13.02.2025 | F25: 0.37 | G25: כן | H25: תקין | I25: תקין | J25: כן | K25: 57 | L25: מאושר | M25: יון!
A26: ערק | B26: 45752 | C26: A104 | E26: 27.03.2025 | F26: 0.37 | G26: כן | H26: תקין | I26: תקין | J26: כן | K26: 40 | L26: מאושר | M26: יון! | N26: ערק גיבורים
A27: ג'ין | B27: 45752 | C27: G8 | E27: 31.03.2025 | F27: 0.37 | G27: כן | H27: תקין | I27: תקין | J27: כן | K27: 40 | L27: מאושר | M27: יון! | N27: ג'ין גיבורים
A28: ערק | B28: 45761 | C28: A104 | E28: 27.03.2025 | F28: 0.37 | G28: כן | H28: תקין | I28: תקין | J28: כן | K28: 100 | L28: מאושר | M28: יון!
A29: ג'ין | B29: 45762 | C29: G8 | E29: 31.03.2025 | F29: 0.37 | G29: כן | H29: תקין | I29: תקין | J29: כן | K29: 148 | L29: מאושר | M29: יון!
A30: ליקריץ | B30: 45768 | C30: E56 | E30: 4.4.2025 | F30: 0.375 | G30: כן | H30: תקין | I30: תקין | J30: כן | K30: 53 | L30: מאושר | M30: יון!
A31: ג'ין | B31: 45775 | C31: G8 | E31: 31.03.2025 | F31: 0.375 | G31: כן | H31: תקין | I31: תקין | J31: כן | K31: 130 | L31: מאושר | M31: יון!
A32: ערק | B32: 45777 | C32: A105 | E32: 07.03.2025 | F32: 0.375 | G32: כן | H32: תקין | I32: תקין | J32: כן | K32: 159 | L32: מאושר | M32: יון!
A33: ברנדי ים תיכוני | B33: 45778 | D33: B4 | E33: 3.05.2025 - 01.05.2025 | F33: 0.4 | G33: כן | H33: תקין | I33: תקין | J33: כן | M33: 1.16 ק"ג קטלב
A34: ג'ין | B34: 45783 | C34: G8 | E34: 31.03.2025 | F34: 0.375 | G34: כן | H34: תקין | I34: תקין | J34: כן | K34: 34 | L34: מאושר | M34: יון!
A35: EDV | B35: 45784 | C35: E57 | E35: 4.4.2025 | F35: 0.375 | G35: כן | H35: תקין | I35: תקין | J35: כן | K35: 82 | L35: מאושר | M35: יון!
A36: ערק | B36: 45792 | C36: A106 | E36: 5.5.2025 | F36: 0.375 | G36: כן | H36: תקין | I36: תקין | J36: כן | K36: 197 | L36: מאושר | M36: יון!
A37: ליקריץ | B37: 45795 | C37: E57 | E37: 4.4.2025 | F37: 0.375 | G37: כן | H37: תקין | I37: תקין | J37: כן | K37: 56 | L37: מאושר | M37: יון!
A38: ג'ין | B38: 45798 | C38: G9 | E38: 21.4.2025 | F38: 0.375 | G38: כן | H38: תקין | I38: תקין | J38: כן | K38: 189 | L38: מאושר | M38: יון!
A39: ערק | B39: 45799 | C39: A107 | E39: 20.05.2025 | F39: 0.375 | G39: כן | H39: תקין | I39: תקין | J39: כן | K39: 189 | L39: מאושר | M39: יון!
A40: EDV | B40: 45806 | C40: E58 | E40: 09.03.2025 | F40: 0.375 | G40: כן | H40: תקין | I40: תקין | J40: כן | K40: 129 | L40: מאושר | M40: יון!
...

Sheet מלאי בקבוקים
B2: סוג משקה | C2: כמות במחסן
B3: EDV | C3: =SUMIF(ביקבוק[סוג משקה],מלאי_בקבוקים[[#This Row],[סוג משקה]], ביקבוק[כמות בקבוקים]) - SUMIF([1]מכירות25!$X$4:$X$200, מלאי_בקבוקים[[#This Row],[סוג משקה]], [1]מכירות25!$Y$4:$Y$200) -> #VALUE!
B4: ערק | C4: =SUMIF(ביקבוק[סוג משקה],מלאי_בקבוקים[[#This Row],[סוג משקה]], ביקבוק[כמות בקבוקים]) - SUMIF([1]מכירות25!$X$4:$X$200, מלאי_בקבוקים[[#This Row],[סוג משקה]], [1]מכירות25!$Y$4:$Y$200) -> #VALUE!
B5: ג'ין | C5: =SUMIF(ביקבוק[סוג משקה],מלאי_בקבוקים[[#This Row],[סוג משקה]], ביקבוק[כמות בקבוקים]) - SUMIF([1]מכירות25!$X$4:$X$200, מלאי_בקבוקים[[#This Row],[סוג משקה]], [1]מכירות25!$Y$4:$Y$200) -> #VALUE!
B6: ליקריץ | C6: =SUMIF(ביקבוק[סוג משקה],מלאי_בקבוקים[[#This Row],[סוג משקה]], ביקבוק[כמות בקבוקים]) - SUMIF([1]מכירות25!$X$4:$X$200, מלאי_בקבוקים[[#This Row],[סוג משקה]], [1]מכירות25!$Y$4:$Y$200) -> #VALUE!
B7: ברנדי VS | C7: =SUMIF(ביקבוק[סוג משקה],מלאי_בקבוקים[[#This Row],[סוג משקה]], ביקבוק[כמות בקבוקים]) - SUMIF([1]מכירות25!$X$4:$X$200, מלאי_בקבוקים[[#This Row],[סוג משקה]], [1]מכירות25!$Y$4:$Y$200) -> #VALUE!
B8: ברנדי VSOP | C8: =SUMIF(ביקבוק[סוג משקה],מלאי_בקבוקים[[#This Row],[סוג משקה]], ביקבוק[כמות בקבוקים]) - SUMIF([1]מכירות25!$X$4:$X$200, מלאי_בקבוקים[[#This Row],[סוג משקה]], [1]מכירות25!$Y$4:$Y$200) -> #VALUE!
B9: ברנדי חורש ים תיכוני | C9: =SUMIF(ביקבוק[סוג משקה],מלאי_בקבוקים[[#This Row],[סוג משקה]], ביקבוק[כמות בקבוקים]) - SUMIF([1]מכירות25!$X$4:$X$200, מלאי_בקבוקים[[#This Row],[סוג משקה]], [1]מכירות25!$Y$4:$Y$200) -> #VALUE!

Sheet מלאי חומרי גלם
B1: שם מסחרי | C1: רכיב | D1: יחידת כמות | E1: מלאי
C2: תמרים גולמי (לפני תסיסה) | D2: ק"ג | E2: ='קבלת תמרים'!H2-תסיסה!K2 -> 1351
C3: תמרים בתסיסה | D3: ק"ג | E3: =תסיסה[] -> 0
C5: ='קבלת חומרי גלם'!Q3 -> בקבוק אובלו (ברנדי) | D5: בקבוק | E5: =SUMIF(קבלת_חומרי_גלם[סוג חומר הגלם], 'מלאי חומרי גלם'!C5, קבלת_חומרי_גלם[משקל/כמות '[ק"ג']]) - SUMIF(ביקבוק[סוג משקה], 'קבלת חומרי גלם'!S7,ביקבוק[כמות בקבוקים]) - SUMIF(ביקבוק[סוג משקה], 'קבלת חומרי גלם'!S8,ביקבוק[כמות בקבוקים]) -> 1381
C6: ='קבלת חומרי גלם'!Q4 -> בקבוק דמוס (ג'ין, EDV) | E6: =SUMIF(קבלת_חומרי_גלם[סוג חומר הגלם], 'מלאי חומרי גלם'!C6, קבלת_חומרי_גלם[משקל/כמות '[ק"ג']]) - SUMIF(ביקבוק[סוג משקה], 'קבלת חומרי גלם'!S3, ביקבוק[כמות בקבוקים]) - SUMIF(ביקבוק[סוג משקה], 'קבלת חומרי גלם'!S5, ביקבוק[כמות בקבוקים]) -> -981
C7: ='קבלת חומרי גלם'!Q5 -> בקבוק לוב (ארק ליקריץ') | E7: =SUMIF(קבלת_חומרי_גלם[סוג חומר הגלם], 'מלאי חומרי גלם'!C7, קבלת_חומרי_גלם[משקל/כמות '[ק"ג']]) - SUMIF(ביקבוק[סוג משקה], 'קבלת חומרי גלם'!S4, ביקבוק[כמות בקבוקים]) - SUMIF(ביקבוק[סוג משקה], 'קבלת חומרי גלם'!S6, ביקבוק[כמות בקבוקים]) -> -2093
C8: ='קבלת חומרי גלם'!Q6 -> פקק - דמוס | E8: =SUMIF(קבלת_חומרי_גלם[סוג חומר הגלם], 'מלאי חומרי גלם'!C8, קבלת_חומרי_גלם[משקל/כמות '[ק"ג']]) - SUMIF(ביקבוק[סוג משקה], 'קבלת חומרי גלם'!S3, ביקבוק[כמות בקבוקים]) - SUMIF(ביקבוק[סוג משקה], 'קבלת חומרי גלם'!S5, ביקבוק[כמות בקבוקים]) -> -1087
C9: ='קבלת חומרי גלם'!Q7 -> פקק - אובלו, לוב | E9: =SUMIF(קבלת_חומרי_גלם[סוג חומר הגלם], 'מלאי חומרי גלם'!C9, קבלת_חומרי_גלם[משקל/כמות '[ק"ג']]) - SUMIF(ביקבוק[סוג משקה], 'קבלת חומרי גלם'!S4, ביקבוק[כמות בקבוקים]) - SUMIF(ביקבוק[סוג משקה], 'קבלת חומרי גלם'!S6, ביקבוק[כמות בקבוקים]) - SUMIF(ביקבוק[סוג משקה], 'קבלת חומרי גלם'!S7, ביקבוק[כמות בקבוקים]) - SUMIF(ביקבוק[סוג משקה], 'קבלת חומרי גלם'!S8, ביקבוק[כמות בקבוקים]) -> -1917
C10: ='קבלת חומרי גלם'!Q8 -> קרטון 6 - אובלו (ברנדי)
C11: ='קבלת חומרי גלם'!Q9 -> קרטון 6 - דמוס (ג'ין, EDV)
C12: ='קבלת חומרי גלם'!Q10 -> קרטון 6 - לוב (ארק ליקריץ')
C13: ='קבלת חומרי גלם'!Q11 -> קרטון בקבוק יחד
C14: ='קבלת חומרי גלם'!Q12 -> קרטון 12 אובלו
C15: ='קבלת חומרי גלם'!Q13 -> קרטון 12 דמוס
C16: ='קבלת חומרי גלם'!Q14 -> קרטון 12 לוב
C17: ='קבלת חומרי גלם'!Q15 -> חביות
C19: ='קבלת חומרי גלם'!O3 -> תויות ערק צוואר | D19: תוית | E19: =SUMIF(קבלת_חומרי_גלם[סוג חומר הגלם], 'מלאי חומרי גלם'!C19, קבלת_חומרי_גלם[משקל/כמות '[ק"ג']]) - SUMIF(ביקבוק[סוג משקה], 'קבלת חומרי גלם'!S4, ביקבוק[כמות בקבוקים]) -> -1936
C20: ='קבלת חומרי גלם'!O4 -> תויות ערק | E20: =SUMIF(קבלת_חומרי_גלם[סוג חומר הגלם], 'מלאי חומרי גלם'!C20, קבלת_חומרי_גלם[משקל/כמות '[ק"ג']]) - SUMIF(ביקבוק[סוג משקה], 'קבלת חומרי גלם'!S4, ביקבוק[כמות בקבוקים]) -> -1936 | G20: הערה: לבדוק איך הספק סופר: האם הכמות היא גם של תוית קדמית וגם אחורית, או כל אחד בנפרד?
C21: ='קבלת חומרי גלם'!O5 -> תויות ליקריץ' צוואר | E21: =SUMIF(קבלת_חומרי_גלם[סוג חומר הגלם], 'מלאי חומרי גלם'!C21, קבלת_חומרי_גלם[משקל/כמות '[ק"ג']]) - SUMIF(ביקבוק[סוג משקה], 'קבלת חומרי גלם'!S6, ביקבוק[כמות בקבוקים]) -> -157
C22: ='קבלת חומרי גלם'!O6 -> תויות ליקריץ' | E22: =SUMIF(קבלת_חומרי_גלם[סוג חומר הגלם], 'מלאי חומרי גלם'!C22, קבלת_חומרי_גלם[משקל/כמות '[ק"ג']]) - SUMIF(ביקבוק[סוג משקה], 'קבלת חומרי גלם'!S6, ביקבוק[כמות בקבוקים]) -> -57 | G22: הערה: לבדוק איך הספק סופר: האם הכמות היא גם של תוית קדמית וגם אחורית, או כל אחד בנפרד?
C23: ='קבלת חומרי גלם'!O7 -> תויות ג'ין צוואר | E23: =SUMIF(קבלת_חומרי_גלם[סוג חומר הגלם], 'מלאי חומרי גלם'!C23, קבלת_חומרי_גלם[משקל/כמות '[ק"ג']]) - SUMIF(ביקבוק[סוג משקה], 'קבלת חומרי גלם'!S5, ביקבוק[כמות בקבוקים]) -> -774
C24: ='קבלת חומרי גלם'!O8 -> תויות ג'ין | E24: =SUMIF(קבלת_חומרי_גלם[סוג חומר הגלם], 'מלאי חומרי גלם'!C24, קבלת_חומרי_גלם[משקל/כמות '[ק"ג']]) - SUMIF(ביקבוק[סוג משקה], 'קבלת חומרי גלם'!S5, ביקבוק[כמות בקבוקים]) -> -748
C25: ='קבלת חומרי גלם'!O9 -> תויות EDV צוואר | E25: =SUMIF(קבלת_חומרי_גלם[סוג חומר הגלם], 'מלאי חומרי גלם'!C25, קבלת_חומרי_גלם[משקל/כמות '[ק"ג']]) - SUMIF(ביקבוק[סוג משקה], 'קבלת חומרי גלם'!S3, ביקבוק[כמות בקבוקים]) -> 87
C26: ='קבלת חומרי גלם'!O10 -> תויות EDV | E26: =SUMIF(קבלת_חומרי_גלם[סוג חומר הגלם], 'מלאי חומרי גלם'!C26, קבלת_חומרי_גלם[משקל/כמות '[ק"ג']]) - SUMIF(ביקבוק[סוג משקה], 'קבלת חומרי גלם'!S3, ביקבוק[כמות בקבוקים]) -> 87
C27: ='קבלת חומרי גלם'!O11 -> תויות ברנדי VS צוואר | E27: =SUMIF(קבלת_חומרי_גלם[סוג חומר הגלם], 'מלאי חומרי גלם'!C27, קבלת_חומרי_גלם[משקל/כמות '[ק"ג']]) - SUMIF(ביקבוק[סוג משקה], 'קבלת חומרי גלם'!S7, ביקבוק[כמות בקבוקים]) -> 628
C28: ='קבלת חומרי גלם'!O12 -> תויות ברנדי VS | E28: =SUMIF(קבלת_חומרי_גלם[סוג חומר הגלם], 'מלאי חומרי גלם'!C28, קבלת_חומרי_גלם[משקל/כמות '[ק"ג']]) - SUMIF(ביקבוק[סוג משקה], 'קבלת חומרי גלם'!S7, ביקבוק[כמות בקבוקים]) -> 628
C29: ='קבלת חומרי גלם'!O13 -> תויות ברנדי VSOP צוואר | E29: =SUMIF(קבלת_חומרי_גלם[סוג חומר הגלם], 'מלאי חומרי גלם'!C29, קבלת_חומרי_גלם[משקל/כמות '[ק"ג']]) - SUMIF(ביקבוק[סוג משקה], 'קבלת חומרי גלם'!S8,ביקבוק[כמות בקבוקים]) -> 1000
C30: ='קבלת חומרי גלם'!O14 -> תויות ברנדי VSOP | E30: =SUMIF(קבלת_חומרי_גלם[סוג חומר הגלם], 'מלאי חומרי גלם'!C30, קבלת_חומרי_גלם[משקל/כמות '[ק"ג']]) - SUMIF(ביקבוק[סוג משקה], 'קבלת חומרי גלם'!S8,ביקבוק[כמות בקבוקים]) -> 1000
C31: ='קבלת חומרי גלם'!O15 -> תוית פקק נחושת | E31: =SUMIF(קבלת_חומרי_גלם[סוג חומר הגלם], 'מלאי חומרי גלם'!C31, קבלת_חומרי_גלם[משקל/כמות '[ק"ג']]) - SUMIF(ביקבוק[סוג משקה], 'קבלת חומרי גלם'!S4, ביקבוק[כמות בקבוקים]) - SUMIF(ביקבוק[סוג משקה], 'קבלת חומרי גלם'!S6, ביקבוק[כמות בקבוקים]) - SUMIF(ביקבוק[סוג משקה], 'קבלת חומרי גלם'!S7, ביקבוק[כמות בקבוקים]) - SUMIF(ביקבוק[סוג משקה], 'קבלת חומרי גלם'!S8, ביקבוק[כמות בקבוקים]) -> -132
C32: ='קבלת חומרי גלם'!O16 -> תוית פקק זהב | E32: =SUMIF(קבלת_חומרי_גלם[סוג חומר הגלם], 'מלאי חומרי גלם'!C8, קבלת_חומרי_גלם[משקל/כמות '[ק"ג']]) - SUMIF(ביקבוק[סוג משקה], 'קבלת חומרי גלם'!S3, ביקבוק[כמות בקבוקים]) - SUMIF(ביקבוק[סוג משקה], 'קבלת חומרי גלם'!S5, ביקבוק[כמות בקבוקים]) -> -1087
B33: ערק
C34: ='קבלת חומרי גלם'!M4 -> זרעי אניס | E34: =SUMIF(קבלת_חומרי_גלם[סוג חומר הגלם], 'מלאי חומרי גלם'!C34, קבלת_חומרי_גלם[משקל/כמות '[ק"ג']]) - COUNTIF(זיקוק_2[סוג], "ערק")*0.5 -> -6.06
C35: ='קבלת חומרי גלם'!M3 -> כוכב אניס | E35: =SUMIF(קבלת_חומרי_גלם[סוג חומר הגלם], 'מלאי חומרי גלם'!C35, קבלת_חומרי_גלם[משקל/כמות '[ק"ג']]) - COUNTIF(זיקוק_2[סוג], "ערק")*0.5 -> -5.69
B36: ליקריץ
C37: ='קבלת חומרי גלם'!M5 -> ליקריץ | E37: =SUMIF(קבלת_חומרי_גלם[סוג חומר הגלם], 'מלאי חומרי גלם'!C37, קבלת_חומרי_גלם[משקל/כמות '[ק"ג']]) - COUNTIF(ביקבוק!A4:A7, 'מלאי חומרי גלם'!C37)*0.5 -> 400.6
B38: ג'ין
C39: ='קבלת חומרי גלם'!M6 -> ערער | E39: =SUMIF(קבלת_חומרי_גלם[סוג חומר הגלם], 'מלאי חומרי גלם'!C39, קבלת_חומרי_גלם[משקל/כמות '[ק"ג']]) - COUNTIF(זיקוק_2[סוג], 'קבלת חומרי גלם'!S5)*1.25 -> -9.07
C40: ='קבלת חומרי גלם'!M7 -> הל | E40: =SUMIF(קבלת_חומרי_גלם[סוג חומר הגלם], 'מלאי חומרי גלם'!C40, קבלת_חומרי_גלם[משקל/כמות '[ק"ג']]) - COUNTIF(זיקוק_2[סוג], 'קבלת חומרי גלם'!S5)*0.01 -> 0.55
C41: ='קבלת חומרי גלם'!M8 -> קינמון | E41: =SUMIF(קבלת_חומרי_גלם[סוג חומר הגלם], 'מלאי חומרי גלם'!C41, קבלת_חומרי_גלם[משקל/כמות '[ק"ג']]) - COUNTIF(זיקוק_2[סוג], 'קבלת חומרי גלם'!S5)*0.005 -> 0.28
C42: ='קבלת חומרי גלם'!M9 -> קמומיל | E42: =SUMIF(קבלת_חומרי_גלם[סוג חומר הגלם], 'מלאי חומרי גלם'!C42, קבלת_חומרי_גלם[משקל/כמות '[ק"ג']]) - COUNTIF(זיקוק_2[סוג], 'קבלת חומרי גלם'!S5)*0.003 -> 0.856
...

Sheet תבלינים
A1: מידה | B1: תבלין | C1: כמות ל130 ל' | D1: כמות ל500 ל'
B2: ערק
A3: ק"ג | B3: זרעי אניס | C3: 0.5 | D3: =C3*4.16666667 -> 2.0833333
A4: ק"ג | B4: כוכבי אניס | C4: 0.5 | D4: =C4*4.16666667 -> 2.0833333
B6: ליקריץ
B7: ליקריץ | D7: =C7*4.16666667 -> 0
B9: ג'ין
A10: ק"ג | B10: ערער פירות | C10: 1.2 | D10: =C10*4.16666667 -> 5
A11: גרם | B11: הל שלם | C11: 0.1 | D11: =C11*4.16666667 -> 0.41666667
A12: גרם | B12: פירות הדר - לימון ליים | C12: 0.07 | D12: =C12*4.16666667 -> 0.29166667
A13: גרם | B13: פירות הדר - תפוז לח | C13: 0.07 | D13: =C13*4.16666667 -> 0.29166667
A14: גרם | B14: מקלות קינמון | C14: 0.05 | D14: =C14*4.16666667 -> 0.20833333
A15: גרם | B15: זרעי כוסברה | C15: 0.15 | D15: =C15*4.16666667 -> 0.625
A16: גרם | B16: פרחי קמומיל | C16: 0.03 | D16: =C16*4.16666667 -> 0.125
A17: גרם | B17: דום (שיזף) | C17: 0.3 | D17: =C17*4.16666667 -> 1.25
A18: גרם | B18: כוכב ריחני | C18: 0.03 | D18: =C18*4.16666667 -> 0.125
A19: גרם | B19: פרעושית | C19: 0.03 | D19: =C19*4.16666667 -> 0.125
B21: ברנדי חורש ים תיכוני
B22: חרוב | D22: =C22*4.16666667 -> 0
B23: אלה | D23: =C23*4.16666667 -> 0
B24: קטלב | D24: =C24*4.16666667 -> 0
D25: =C25*4.16666667 -> 0
